[2024-12-03T13:56:41.531+0000] {local_task_job_runner.py:123} INFO - ::group::Pre task execution logs
[2024-12-03T13:56:41.554+0000] {taskinstance.py:2613} INFO - Dependencies all met for dep_context=non-requeueable deps ti=<TaskInstance: etl_data_pipeline_mongodb.load_data manual__2024-12-02T23:55:19.358606+00:00 [queued]>
[2024-12-03T13:56:41.565+0000] {taskinstance.py:2613} INFO - Dependencies all met for dep_context=requeueable deps ti=<TaskInstance: etl_data_pipeline_mongodb.load_data manual__2024-12-02T23:55:19.358606+00:00 [queued]>
[2024-12-03T13:56:41.567+0000] {taskinstance.py:2866} INFO - Starting attempt 2 of 2
[2024-12-03T13:56:41.587+0000] {taskinstance.py:2889} INFO - Executing <Task(PythonOperator): load_data> on 2024-12-02 23:55:19.358606+00:00
[2024-12-03T13:56:41.600+0000] {warnings.py:112} WARNING - /home/***/.local/lib/python3.12/site-packages/***/task/task_runner/standard_task_runner.py:70: DeprecationWarning: This process (pid=77) is multi-threaded, use of fork() may lead to deadlocks in the child.
  pid = os.fork()

[2024-12-03T13:56:41.604+0000] {standard_task_runner.py:72} INFO - Started process 80 to run task
[2024-12-03T13:56:41.604+0000] {standard_task_runner.py:104} INFO - Running: ['***', 'tasks', 'run', 'etl_data_pipeline_mongodb', 'load_data', 'manual__2024-12-02T23:55:19.358606+00:00', '--job-id', '163', '--raw', '--subdir', 'DAGS_FOLDER/etl_data_pipeline_mongodb.py', '--cfg-path', '/tmp/tmpg_iy92gy']
[2024-12-03T13:56:41.605+0000] {standard_task_runner.py:105} INFO - Job 163: Subtask load_data
[2024-12-03T13:56:41.662+0000] {task_command.py:467} INFO - Running <TaskInstance: etl_data_pipeline_mongodb.load_data manual__2024-12-02T23:55:19.358606+00:00 [running]> on host ed9532b68cd8
[2024-12-03T13:56:41.790+0000] {taskinstance.py:3132} INFO - Exporting env vars: AIRFLOW_CTX_DAG_OWNER='***' AIRFLOW_CTX_DAG_ID='etl_data_pipeline_mongodb' AIRFLOW_CTX_TASK_ID='load_data' AIRFLOW_CTX_EXECUTION_DATE='2024-12-02T23:55:19.358606+00:00' AIRFLOW_CTX_TRY_NUMBER='2' AIRFLOW_CTX_DAG_RUN_ID='manual__2024-12-02T23:55:19.358606+00:00'
[2024-12-03T13:56:41.792+0000] {logging_mixin.py:190} INFO - Task instance is in running state
[2024-12-03T13:56:41.792+0000] {logging_mixin.py:190} INFO -  Previous state of the Task instance: queued
[2024-12-03T13:56:41.793+0000] {logging_mixin.py:190} INFO - Current task name:load_data state:running start_date:2024-12-03 13:56:41.555720+00:00
[2024-12-03T13:56:41.794+0000] {logging_mixin.py:190} INFO - Dag name:etl_data_pipeline_mongodb and current dag run status:running
[2024-12-03T13:56:41.794+0000] {taskinstance.py:731} INFO - ::endgroup::
[2024-12-03T13:56:41.844+0000] {taskinstance.py:3311} ERROR - Task failed with exception
Traceback (most recent call last):
  File "/home/airflow/.local/lib/python3.12/site-packages/airflow/models/taskinstance.py", line 767, in _execute_task
    result = _execute_callable(context=context, **execute_callable_kwargs)
             ^^^^^^^^^^^^^^^^^^^^^^^^^^^^^^^^^^^^^^^^^^^^^^^^^^^^^^^^^^^^^
  File "/home/airflow/.local/lib/python3.12/site-packages/airflow/models/taskinstance.py", line 733, in _execute_callable
    return ExecutionCallableRunner(
           ^^^^^^^^^^^^^^^^^^^^^^^^
  File "/home/airflow/.local/lib/python3.12/site-packages/airflow/utils/operator_helpers.py", line 252, in run
    return self.func(*args, **kwargs)
           ^^^^^^^^^^^^^^^^^^^^^^^^^^
  File "/home/airflow/.local/lib/python3.12/site-packages/airflow/models/baseoperator.py", line 417, in wrapper
    return func(self, *args, **kwargs)
           ^^^^^^^^^^^^^^^^^^^^^^^^^^^
  File "/home/airflow/.local/lib/python3.12/site-packages/airflow/operators/python.py", line 238, in execute
    return_value = self.execute_callable()
                   ^^^^^^^^^^^^^^^^^^^^^^^
  File "/home/airflow/.local/lib/python3.12/site-packages/airflow/operators/python.py", line 256, in execute_callable
    return runner.run(*self.op_args, **self.op_kwargs)
           ^^^^^^^^^^^^^^^^^^^^^^^^^^^^^^^^^^^^^^^^^^^
  File "/home/airflow/.local/lib/python3.12/site-packages/airflow/utils/operator_helpers.py", line 252, in run
    return self.func(*args, **kwargs)
           ^^^^^^^^^^^^^^^^^^^^^^^^^^
  File "/opt/airflow/dags/etl_data_pipeline_mongodb.py", line 34, in load_data
    with open("/tmp/cleaned_data.json", "r") as file:
         ^^^^^^^^^^^^^^^^^^^^^^^^^^^^^^^^^^^
FileNotFoundError: [Errno 2] No such file or directory: '/tmp/cleaned_data.json'
[2024-12-03T13:56:41.856+0000] {logging_mixin.py:190} INFO - Task instance in failure state
[2024-12-03T13:56:41.857+0000] {logging_mixin.py:190} INFO - Task start:2024-12-03 13:56:41.555720+00:00 end:2024-12-03 13:56:41.855768+00:00 duration:0.300048
[2024-12-03T13:56:41.857+0000] {logging_mixin.py:190} INFO - Task:<Task(PythonOperator): load_data> dag:<DAG: etl_data_pipeline_mongodb> dagrun:<DagRun etl_data_pipeline_mongodb @ 2024-12-02 23:55:19.358606+00:00: manual__2024-12-02T23:55:19.358606+00:00, state:running, queued_at: 2024-12-02 23:55:19.375945+00:00. externally triggered: True>
[2024-12-03T13:56:41.858+0000] {logging_mixin.py:190} INFO - Failure caused by [Errno 2] No such file or directory: '/tmp/cleaned_data.json'
[2024-12-03T13:56:41.858+0000] {taskinstance.py:1225} INFO - Marking task as FAILED. dag_id=etl_data_pipeline_mongodb, task_id=load_data, run_id=manual__2024-12-02T23:55:19.358606+00:00, execution_date=20241202T235519, start_date=20241203T135641, end_date=20241203T135641
[2024-12-03T13:56:41.879+0000] {taskinstance.py:340} INFO - ::group::Post task execution logs
[2024-12-03T13:56:41.879+0000] {standard_task_runner.py:124} ERROR - Failed to execute job 163 for task load_data ([Errno 2] No such file or directory: '/tmp/cleaned_data.json'; 80)
Traceback (most recent call last):
  File "/home/airflow/.local/lib/python3.12/site-packages/airflow/task/task_runner/standard_task_runner.py", line 117, in _start_by_fork
    ret = args.func(args, dag=self.dag)
          ^^^^^^^^^^^^^^^^^^^^^^^^^^^^^
  File "/home/airflow/.local/lib/python3.12/site-packages/airflow/cli/cli_config.py", line 49, in command
    return func(*args, **kwargs)
           ^^^^^^^^^^^^^^^^^^^^^
  File "/home/airflow/.local/lib/python3.12/site-packages/airflow/utils/cli.py", line 116, in wrapper
    return f(*args, **kwargs)
           ^^^^^^^^^^^^^^^^^^
  File "/home/airflow/.local/lib/python3.12/site-packages/airflow/cli/commands/task_command.py", line 483, in task_run
    task_return_code = _run_task_by_selected_method(args, _dag, ti)
                       ^^^^^^^^^^^^^^^^^^^^^^^^^^^^^^^^^^^^^^^^^^^^
  File "/home/airflow/.local/lib/python3.12/site-packages/airflow/cli/commands/task_command.py", line 256, in _run_task_by_selected_method
    return _run_raw_task(args, ti)
           ^^^^^^^^^^^^^^^^^^^^^^^
  File "/home/airflow/.local/lib/python3.12/site-packages/airflow/cli/commands/task_command.py", line 341, in _run_raw_task
    return ti._run_raw_task(
           ^^^^^^^^^^^^^^^^^
  File "/home/airflow/.local/lib/python3.12/site-packages/airflow/utils/session.py", line 97, in wrapper
    return func(*args, session=session, **kwargs)
           ^^^^^^^^^^^^^^^^^^^^^^^^^^^^^^^^^^^^^^
  File "/home/airflow/.local/lib/python3.12/site-packages/airflow/models/taskinstance.py", line 3005, in _run_raw_task
    return _run_raw_task(
           ^^^^^^^^^^^^^^
  File "/home/airflow/.local/lib/python3.12/site-packages/airflow/models/taskinstance.py", line 273, in _run_raw_task
    TaskInstance._execute_task_with_callbacks(
  File "/home/airflow/.local/lib/python3.12/site-packages/airflow/models/taskinstance.py", line 3159, in _execute_task_with_callbacks
    result = self._execute_task(context, task_orig)
             ^^^^^^^^^^^^^^^^^^^^^^^^^^^^^^^^^^^^^^
  File "/home/airflow/.local/lib/python3.12/site-packages/airflow/models/taskinstance.py", line 3183, in _execute_task
    return _execute_task(self, context, task_orig)
           ^^^^^^^^^^^^^^^^^^^^^^^^^^^^^^^^^^^^^^^
  File "/home/airflow/.local/lib/python3.12/site-packages/airflow/models/taskinstance.py", line 767, in _execute_task
    result = _execute_callable(context=context, **execute_callable_kwargs)
             ^^^^^^^^^^^^^^^^^^^^^^^^^^^^^^^^^^^^^^^^^^^^^^^^^^^^^^^^^^^^^
  File "/home/airflow/.local/lib/python3.12/site-packages/airflow/models/taskinstance.py", line 733, in _execute_callable
    return ExecutionCallableRunner(
           ^^^^^^^^^^^^^^^^^^^^^^^^
  File "/home/airflow/.local/lib/python3.12/site-packages/airflow/utils/operator_helpers.py", line 252, in run
    return self.func(*args, **kwargs)
           ^^^^^^^^^^^^^^^^^^^^^^^^^^
  File "/home/airflow/.local/lib/python3.12/site-packages/airflow/models/baseoperator.py", line 417, in wrapper
    return func(self, *args, **kwargs)
           ^^^^^^^^^^^^^^^^^^^^^^^^^^^
  File "/home/airflow/.local/lib/python3.12/site-packages/airflow/operators/python.py", line 238, in execute
    return_value = self.execute_callable()
                   ^^^^^^^^^^^^^^^^^^^^^^^
  File "/home/airflow/.local/lib/python3.12/site-packages/airflow/operators/python.py", line 256, in execute_callable
    return runner.run(*self.op_args, **self.op_kwargs)
           ^^^^^^^^^^^^^^^^^^^^^^^^^^^^^^^^^^^^^^^^^^^
  File "/home/airflow/.local/lib/python3.12/site-packages/airflow/utils/operator_helpers.py", line 252, in run
    return self.func(*args, **kwargs)
           ^^^^^^^^^^^^^^^^^^^^^^^^^^
  File "/opt/airflow/dags/etl_data_pipeline_mongodb.py", line 34, in load_data
    with open("/tmp/cleaned_data.json", "r") as file:
         ^^^^^^^^^^^^^^^^^^^^^^^^^^^^^^^^^^^
FileNotFoundError: [Errno 2] No such file or directory: '/tmp/cleaned_data.json'
[2024-12-03T13:56:41.901+0000] {local_task_job_runner.py:266} INFO - Task exited with return code 1
[2024-12-03T13:56:41.925+0000] {taskinstance.py:3895} INFO - 0 downstream tasks scheduled from follow-on schedule check
[2024-12-03T13:56:41.930+0000] {local_task_job_runner.py:245} INFO - ::endgroup::
